[2024-07-15T10:28:39.278+0000] {taskinstance.py:1103} INFO - Dependencies all met for dep_context=non-requeueable deps ti=<TaskInstance: run_remote_jupyter_notebook.run_notebook scheduled__2023-03-16T00:00:00+00:00 [queued]>
[2024-07-15T10:28:39.288+0000] {taskinstance.py:1103} INFO - Dependencies all met for dep_context=requeueable deps ti=<TaskInstance: run_remote_jupyter_notebook.run_notebook scheduled__2023-03-16T00:00:00+00:00 [queued]>
[2024-07-15T10:28:39.289+0000] {taskinstance.py:1308} INFO - Starting attempt 1 of 2
[2024-07-15T10:28:39.311+0000] {taskinstance.py:1327} INFO - Executing <Task(PythonOperator): run_notebook> on 2023-03-16 00:00:00+00:00
[2024-07-15T10:28:39.319+0000] {standard_task_runner.py:57} INFO - Started process 2202 to run task
[2024-07-15T10:28:39.327+0000] {standard_task_runner.py:84} INFO - Running: ['***', 'tasks', 'run', 'run_remote_jupyter_notebook', 'run_notebook', 'scheduled__2023-03-16T00:00:00+00:00', '--job-id', '614', '--raw', '--subdir', 'DAGS_FOLDER/run_notebook.py', '--cfg-path', '/tmp/tmpcrn0sksc']
[2024-07-15T10:28:39.336+0000] {standard_task_runner.py:85} INFO - Job 614: Subtask run_notebook
[2024-07-15T10:28:39.412+0000] {task_command.py:410} INFO - Running <TaskInstance: run_remote_jupyter_notebook.run_notebook scheduled__2023-03-16T00:00:00+00:00 [running]> on host ddd5ef3b0a5c
[2024-07-15T10:28:39.723+0000] {taskinstance.py:1547} INFO - Exporting env vars: AIRFLOW_CTX_DAG_OWNER='***' AIRFLOW_CTX_DAG_ID='run_remote_jupyter_notebook' AIRFLOW_CTX_TASK_ID='run_notebook' AIRFLOW_CTX_EXECUTION_DATE='2023-03-16T00:00:00+00:00' AIRFLOW_CTX_TRY_NUMBER='1' AIRFLOW_CTX_DAG_RUN_ID='scheduled__2023-03-16T00:00:00+00:00'
[2024-07-15T10:28:39.731+0000] {taskinstance.py:1824} ERROR - Task failed with exception
Traceback (most recent call last):
  File "/home/airflow/.local/lib/python3.7/site-packages/urllib3/connection.py", line 175, in _new_conn
    (self._dns_host, self.port), self.timeout, **extra_kw
  File "/home/airflow/.local/lib/python3.7/site-packages/urllib3/util/connection.py", line 95, in create_connection
    raise err
  File "/home/airflow/.local/lib/python3.7/site-packages/urllib3/util/connection.py", line 85, in create_connection
    sock.connect(sa)
ConnectionRefusedError: [Errno 111] Connection refused

During handling of the above exception, another exception occurred:

Traceback (most recent call last):
  File "/home/airflow/.local/lib/python3.7/site-packages/urllib3/connectionpool.py", line 710, in urlopen
    chunked=chunked,
  File "/home/airflow/.local/lib/python3.7/site-packages/urllib3/connectionpool.py", line 398, in _make_request
    conn.request(method, url, **httplib_request_kw)
  File "/home/airflow/.local/lib/python3.7/site-packages/urllib3/connection.py", line 244, in request
    super(HTTPConnection, self).request(method, url, body=body, headers=headers)
  File "/usr/local/lib/python3.7/http/client.py", line 1281, in request
    self._send_request(method, url, body, headers, encode_chunked)
  File "/usr/local/lib/python3.7/http/client.py", line 1327, in _send_request
    self.endheaders(body, encode_chunked=encode_chunked)
  File "/usr/local/lib/python3.7/http/client.py", line 1276, in endheaders
    self._send_output(message_body, encode_chunked=encode_chunked)
  File "/usr/local/lib/python3.7/http/client.py", line 1036, in _send_output
    self.send(msg)
  File "/usr/local/lib/python3.7/http/client.py", line 976, in send
    self.connect()
  File "/home/airflow/.local/lib/python3.7/site-packages/urllib3/connection.py", line 205, in connect
    conn = self._new_conn()
  File "/home/airflow/.local/lib/python3.7/site-packages/urllib3/connection.py", line 187, in _new_conn
    self, "Failed to establish a new connection: %s" % e
urllib3.exceptions.NewConnectionError: <urllib3.connection.HTTPConnection object at 0x7f03b7b31d50>: Failed to establish a new connection: [Errno 111] Connection refused

During handling of the above exception, another exception occurred:

Traceback (most recent call last):
  File "/home/airflow/.local/lib/python3.7/site-packages/requests/adapters.py", line 497, in send
    chunked=chunked,
  File "/home/airflow/.local/lib/python3.7/site-packages/urllib3/connectionpool.py", line 788, in urlopen
    method, url, error=e, _pool=self, _stacktrace=sys.exc_info()[2]
  File "/home/airflow/.local/lib/python3.7/site-packages/urllib3/util/retry.py", line 592, in increment
    raise MaxRetryError(_pool, url, error or ResponseError(cause))
urllib3.exceptions.MaxRetryError: HTTPConnectionPool(host='127.0.0.1', port=8888): Max retries exceeded with url: /notebooks/Notebooks/notebook.ipynb?token=e294adf9101f365057cd621463e551bbcebdff24796d190c (Caused by NewConnectionError('<urllib3.connection.HTTPConnection object at 0x7f03b7b31d50>: Failed to establish a new connection: [Errno 111] Connection refused'))

During handling of the above exception, another exception occurred:

Traceback (most recent call last):
  File "/home/airflow/.local/lib/python3.7/site-packages/airflow/operators/python.py", line 181, in execute
    return_value = self.execute_callable()
  File "/home/airflow/.local/lib/python3.7/site-packages/airflow/operators/python.py", line 198, in execute_callable
    return self.python_callable(*self.op_args, **self.op_kwargs)
  File "/opt/airflow/dags/run_notebook.py", line 16, in execute_remote_notebook
    response = requests.get(notebook_url)
  File "/home/airflow/.local/lib/python3.7/site-packages/requests/api.py", line 73, in get
    return request("get", url, params=params, **kwargs)
  File "/home/airflow/.local/lib/python3.7/site-packages/requests/api.py", line 59, in request
    return session.request(method=method, url=url, **kwargs)
  File "/home/airflow/.local/lib/python3.7/site-packages/requests/sessions.py", line 587, in request
    resp = self.send(prep, **send_kwargs)
  File "/home/airflow/.local/lib/python3.7/site-packages/requests/sessions.py", line 701, in send
    r = adapter.send(request, **kwargs)
  File "/home/airflow/.local/lib/python3.7/site-packages/requests/adapters.py", line 519, in send
    raise ConnectionError(e, request=request)
requests.exceptions.ConnectionError: HTTPConnectionPool(host='127.0.0.1', port=8888): Max retries exceeded with url: /notebooks/Notebooks/notebook.ipynb?token=e294adf9101f365057cd621463e551bbcebdff24796d190c (Caused by NewConnectionError('<urllib3.connection.HTTPConnection object at 0x7f03b7b31d50>: Failed to establish a new connection: [Errno 111] Connection refused'))
[2024-07-15T10:28:39.756+0000] {taskinstance.py:1350} INFO - Marking task as UP_FOR_RETRY. dag_id=run_remote_jupyter_notebook, task_id=run_notebook, execution_date=20230316T000000, start_date=20240715T102839, end_date=20240715T102839
[2024-07-15T10:28:39.775+0000] {standard_task_runner.py:109} ERROR - Failed to execute job 614 for task run_notebook (HTTPConnectionPool(host='127.0.0.1', port=8888): Max retries exceeded with url: /notebooks/Notebooks/notebook.ipynb?token=e294adf9101f365057cd621463e551bbcebdff24796d190c (Caused by NewConnectionError('<urllib3.connection.HTTPConnection object at 0x7f03b7b31d50>: Failed to establish a new connection: [Errno 111] Connection refused')); 2202)
[2024-07-15T10:28:39.820+0000] {local_task_job_runner.py:225} INFO - Task exited with return code 1
[2024-07-15T10:28:39.837+0000] {taskinstance.py:2651} INFO - 0 downstream tasks scheduled from follow-on schedule check
[2024-07-18T06:31:04.132+0000] {taskinstance.py:1103} INFO - Dependencies all met for dep_context=non-requeueable deps ti=<TaskInstance: run_remote_jupyter_notebook.run_notebook scheduled__2023-03-16T00:00:00+00:00 [queued]>
[2024-07-18T06:31:04.152+0000] {taskinstance.py:1103} INFO - Dependencies all met for dep_context=requeueable deps ti=<TaskInstance: run_remote_jupyter_notebook.run_notebook scheduled__2023-03-16T00:00:00+00:00 [queued]>
[2024-07-18T06:31:04.154+0000] {taskinstance.py:1308} INFO - Starting attempt 1 of 2
[2024-07-18T06:31:04.188+0000] {taskinstance.py:1327} INFO - Executing <Task(PythonOperator): run_notebook> on 2023-03-16 00:00:00+00:00
[2024-07-18T06:31:04.202+0000] {standard_task_runner.py:57} INFO - Started process 3864 to run task
[2024-07-18T06:31:04.212+0000] {standard_task_runner.py:84} INFO - Running: ['***', 'tasks', 'run', 'run_remote_jupyter_notebook', 'run_notebook', 'scheduled__2023-03-16T00:00:00+00:00', '--job-id', '76', '--raw', '--subdir', 'DAGS_FOLDER/run_notebook.py', '--cfg-path', '/tmp/tmpuuxsjhs6']
[2024-07-18T06:31:04.216+0000] {standard_task_runner.py:85} INFO - Job 76: Subtask run_notebook
[2024-07-18T06:31:04.385+0000] {task_command.py:410} INFO - Running <TaskInstance: run_remote_jupyter_notebook.run_notebook scheduled__2023-03-16T00:00:00+00:00 [running]> on host 4379a2f533f3
[2024-07-18T06:31:04.578+0000] {taskinstance.py:1547} INFO - Exporting env vars: AIRFLOW_CTX_DAG_OWNER='***' AIRFLOW_CTX_DAG_ID='run_remote_jupyter_notebook' AIRFLOW_CTX_TASK_ID='run_notebook' AIRFLOW_CTX_EXECUTION_DATE='2023-03-16T00:00:00+00:00' AIRFLOW_CTX_TRY_NUMBER='1' AIRFLOW_CTX_DAG_RUN_ID='scheduled__2023-03-16T00:00:00+00:00'
[2024-07-18T06:31:10.883+0000] {logging_mixin.py:149} INFO - Notebook executed and updated successfully on the server.
[2024-07-18T06:31:10.884+0000] {python.py:183} INFO - Done. Returned value was: None
[2024-07-18T06:31:10.896+0000] {taskinstance.py:1350} INFO - Marking task as SUCCESS. dag_id=run_remote_jupyter_notebook, task_id=run_notebook, execution_date=20230316T000000, start_date=20240718T063104, end_date=20240718T063110
[2024-07-18T06:31:10.968+0000] {local_task_job_runner.py:225} INFO - Task exited with return code 0
[2024-07-18T06:31:10.999+0000] {taskinstance.py:2651} INFO - 0 downstream tasks scheduled from follow-on schedule check
[2024-07-18T06:54:38.897+0000] {taskinstance.py:1103} INFO - Dependencies all met for dep_context=non-requeueable deps ti=<TaskInstance: run_remote_jupyter_notebook.run_notebook scheduled__2023-03-16T00:00:00+00:00 [queued]>
[2024-07-18T06:54:38.944+0000] {taskinstance.py:1103} INFO - Dependencies all met for dep_context=requeueable deps ti=<TaskInstance: run_remote_jupyter_notebook.run_notebook scheduled__2023-03-16T00:00:00+00:00 [queued]>
[2024-07-18T06:54:38.945+0000] {taskinstance.py:1308} INFO - Starting attempt 1 of 2
[2024-07-18T06:54:39.006+0000] {taskinstance.py:1327} INFO - Executing <Task(PythonOperator): run_notebook> on 2023-03-16 00:00:00+00:00
[2024-07-18T06:54:39.019+0000] {standard_task_runner.py:57} INFO - Started process 4075 to run task
[2024-07-18T06:54:39.028+0000] {standard_task_runner.py:84} INFO - Running: ['***', 'tasks', 'run', 'run_remote_jupyter_notebook', 'run_notebook', 'scheduled__2023-03-16T00:00:00+00:00', '--job-id', '75', '--raw', '--subdir', 'DAGS_FOLDER/run_notebook.py', '--cfg-path', '/tmp/tmpktzxoud9']
[2024-07-18T06:54:39.033+0000] {standard_task_runner.py:85} INFO - Job 75: Subtask run_notebook
[2024-07-18T06:54:39.178+0000] {task_command.py:410} INFO - Running <TaskInstance: run_remote_jupyter_notebook.run_notebook scheduled__2023-03-16T00:00:00+00:00 [running]> on host 6c8b3b9a6388
[2024-07-18T06:54:39.354+0000] {taskinstance.py:1547} INFO - Exporting env vars: AIRFLOW_CTX_DAG_OWNER='***' AIRFLOW_CTX_DAG_ID='run_remote_jupyter_notebook' AIRFLOW_CTX_TASK_ID='run_notebook' AIRFLOW_CTX_EXECUTION_DATE='2023-03-16T00:00:00+00:00' AIRFLOW_CTX_TRY_NUMBER='1' AIRFLOW_CTX_DAG_RUN_ID='scheduled__2023-03-16T00:00:00+00:00'
[2024-07-18T06:54:43.560+0000] {logging_mixin.py:149} INFO - Notebook executed and updated successfully on the server.
[2024-07-18T06:54:43.564+0000] {python.py:183} INFO - Done. Returned value was: None
[2024-07-18T06:54:43.599+0000] {taskinstance.py:1350} INFO - Marking task as SUCCESS. dag_id=run_remote_jupyter_notebook, task_id=run_notebook, execution_date=20230316T000000, start_date=20240718T065438, end_date=20240718T065443
[2024-07-18T06:54:43.669+0000] {local_task_job_runner.py:225} INFO - Task exited with return code 0
[2024-07-18T06:54:43.716+0000] {taskinstance.py:2651} INFO - 0 downstream tasks scheduled from follow-on schedule check
