[2024-07-15T09:28:18.326+0000] {taskinstance.py:1103} INFO - Dependencies all met for dep_context=non-requeueable deps ti=<TaskInstance: run_jupyter_notebook.run_notebook scheduled__2023-01-13T00:00:00+00:00 [queued]>
[2024-07-15T09:28:18.344+0000] {taskinstance.py:1103} INFO - Dependencies all met for dep_context=requeueable deps ti=<TaskInstance: run_jupyter_notebook.run_notebook scheduled__2023-01-13T00:00:00+00:00 [queued]>
[2024-07-15T09:28:18.344+0000] {taskinstance.py:1308} INFO - Starting attempt 1 of 2
[2024-07-15T09:28:18.383+0000] {taskinstance.py:1327} INFO - Executing <Task(PythonOperator): run_notebook> on 2023-01-13 00:00:00+00:00
[2024-07-15T09:28:18.400+0000] {standard_task_runner.py:57} INFO - Started process 206 to run task
[2024-07-15T09:28:18.410+0000] {standard_task_runner.py:84} INFO - Running: ['***', 'tasks', 'run', 'run_jupyter_notebook', 'run_notebook', 'scheduled__2023-01-13T00:00:00+00:00', '--job-id', '14', '--raw', '--subdir', 'DAGS_FOLDER/run_notebook.py', '--cfg-path', '/tmp/tmply9vite5']
[2024-07-15T09:28:18.420+0000] {standard_task_runner.py:85} INFO - Job 14: Subtask run_notebook
[2024-07-15T09:28:18.554+0000] {task_command.py:410} INFO - Running <TaskInstance: run_jupyter_notebook.run_notebook scheduled__2023-01-13T00:00:00+00:00 [running]> on host 0aeef3766ac4
[2024-07-15T09:28:18.714+0000] {taskinstance.py:1547} INFO - Exporting env vars: AIRFLOW_CTX_DAG_OWNER='***' AIRFLOW_CTX_DAG_ID='run_jupyter_notebook' AIRFLOW_CTX_TASK_ID='run_notebook' AIRFLOW_CTX_EXECUTION_DATE='2023-01-13T00:00:00+00:00' AIRFLOW_CTX_TRY_NUMBER='1' AIRFLOW_CTX_DAG_RUN_ID='scheduled__2023-01-13T00:00:00+00:00'
[2024-07-15T09:28:18.716+0000] {taskinstance.py:1824} ERROR - Task failed with exception
Traceback (most recent call last):
  File "/home/airflow/.local/lib/python3.7/site-packages/airflow/operators/python.py", line 181, in execute
    return_value = self.execute_callable()
  File "/home/airflow/.local/lib/python3.7/site-packages/airflow/operators/python.py", line 198, in execute_callable
    return self.python_callable(*self.op_args, **self.op_kwargs)
  File "/opt/airflow/dags/run_notebook.py", line 11, in execute_notebook
    with open(notebook_path) as f:
FileNotFoundError: [Errno 2] No such file or directory: './notebooks/notebook.ipynb'
[2024-07-15T09:28:18.726+0000] {taskinstance.py:1350} INFO - Marking task as UP_FOR_RETRY. dag_id=run_jupyter_notebook, task_id=run_notebook, execution_date=20230113T000000, start_date=20240715T092818, end_date=20240715T092818
[2024-07-15T09:28:18.737+0000] {standard_task_runner.py:109} ERROR - Failed to execute job 14 for task run_notebook ([Errno 2] No such file or directory: './notebooks/notebook.ipynb'; 206)
[2024-07-15T09:28:18.748+0000] {local_task_job_runner.py:225} INFO - Task exited with return code 1
[2024-07-15T09:28:18.764+0000] {taskinstance.py:2651} INFO - 0 downstream tasks scheduled from follow-on schedule check
