[2024-07-15T11:04:38.009+0000] {taskinstance.py:1103} INFO - Dependencies all met for dep_context=non-requeueable deps ti=<TaskInstance: run_remote_jupyter_notebook.run_notebook scheduled__2023-06-29T00:00:00+00:00 [queued]>
[2024-07-15T11:04:38.026+0000] {taskinstance.py:1103} INFO - Dependencies all met for dep_context=requeueable deps ti=<TaskInstance: run_remote_jupyter_notebook.run_notebook scheduled__2023-06-29T00:00:00+00:00 [queued]>
[2024-07-15T11:04:38.027+0000] {taskinstance.py:1308} INFO - Starting attempt 1 of 2
[2024-07-15T11:04:38.105+0000] {taskinstance.py:1327} INFO - Executing <Task(PythonOperator): run_notebook> on 2023-06-29 00:00:00+00:00
[2024-07-15T11:04:38.117+0000] {standard_task_runner.py:57} INFO - Started process 853 to run task
[2024-07-15T11:04:38.134+0000] {standard_task_runner.py:84} INFO - Running: ['***', 'tasks', 'run', 'run_remote_jupyter_notebook', 'run_notebook', 'scheduled__2023-06-29T00:00:00+00:00', '--job-id', '803', '--raw', '--subdir', 'DAGS_FOLDER/run_notebook.py', '--cfg-path', '/tmp/tmp4th5aem9']
[2024-07-15T11:04:38.138+0000] {standard_task_runner.py:85} INFO - Job 803: Subtask run_notebook
[2024-07-15T11:04:38.277+0000] {task_command.py:410} INFO - Running <TaskInstance: run_remote_jupyter_notebook.run_notebook scheduled__2023-06-29T00:00:00+00:00 [running]> on host 9f73ee97e438
[2024-07-15T11:04:39.119+0000] {taskinstance.py:1547} INFO - Exporting env vars: AIRFLOW_CTX_DAG_OWNER='***' AIRFLOW_CTX_DAG_ID='run_remote_jupyter_notebook' AIRFLOW_CTX_TASK_ID='run_notebook' AIRFLOW_CTX_EXECUTION_DATE='2023-06-29T00:00:00+00:00' AIRFLOW_CTX_TRY_NUMBER='1' AIRFLOW_CTX_DAG_RUN_ID='scheduled__2023-06-29T00:00:00+00:00'
[2024-07-15T11:04:39.121+0000] {run_notebook.py:14} INFO - Attempting to connect to http://host.docker.internal:8888/notebooks/Notebooks/notebook.ipynb?token=3b56a766afdef52d8fa1fa30bde9f5e0755d377370514cb6
[2024-07-15T11:04:39.154+0000] {run_notebook.py:39} ERROR - Error connecting to notebook: Expecting value: line 1 column 1 (char 0)
[2024-07-15T11:04:39.155+0000] {taskinstance.py:1824} ERROR - Task failed with exception
Traceback (most recent call last):
  File "/home/airflow/.local/lib/python3.7/site-packages/requests/models.py", line 971, in json
    return complexjson.loads(self.text, **kwargs)
  File "/usr/local/lib/python3.7/json/__init__.py", line 348, in loads
    return _default_decoder.decode(s)
  File "/usr/local/lib/python3.7/json/decoder.py", line 337, in decode
    obj, end = self.raw_decode(s, idx=_w(s, 0).end())
  File "/usr/local/lib/python3.7/json/decoder.py", line 355, in raw_decode
    raise JSONDecodeError("Expecting value", s, err.value) from None
json.decoder.JSONDecodeError: Expecting value: line 1 column 1 (char 0)

During handling of the above exception, another exception occurred:

Traceback (most recent call last):
  File "/home/airflow/.local/lib/python3.7/site-packages/airflow/operators/python.py", line 181, in execute
    return_value = self.execute_callable()
  File "/home/airflow/.local/lib/python3.7/site-packages/airflow/operators/python.py", line 198, in execute_callable
    return self.python_callable(*self.op_args, **self.op_kwargs)
  File "/opt/airflow/dags/run_notebook.py", line 22, in execute_remote_notebook
    notebook_content = response.json()
  File "/home/airflow/.local/lib/python3.7/site-packages/requests/models.py", line 975, in json
    raise RequestsJSONDecodeError(e.msg, e.doc, e.pos)
requests.exceptions.JSONDecodeError: Expecting value: line 1 column 1 (char 0)
[2024-07-15T11:04:39.177+0000] {taskinstance.py:1350} INFO - Marking task as UP_FOR_RETRY. dag_id=run_remote_jupyter_notebook, task_id=run_notebook, execution_date=20230629T000000, start_date=20240715T110438, end_date=20240715T110439
[2024-07-15T11:04:39.204+0000] {standard_task_runner.py:109} ERROR - Failed to execute job 803 for task run_notebook (Expecting value: line 1 column 1 (char 0); 853)
[2024-07-15T11:04:39.275+0000] {local_task_job_runner.py:225} INFO - Task exited with return code 1
[2024-07-15T11:04:39.416+0000] {taskinstance.py:2651} INFO - 0 downstream tasks scheduled from follow-on schedule check
[2024-07-18T06:56:06.711+0000] {taskinstance.py:1103} INFO - Dependencies all met for dep_context=non-requeueable deps ti=<TaskInstance: run_remote_jupyter_notebook.run_notebook scheduled__2023-06-29T00:00:00+00:00 [queued]>
[2024-07-18T06:56:06.735+0000] {taskinstance.py:1103} INFO - Dependencies all met for dep_context=requeueable deps ti=<TaskInstance: run_remote_jupyter_notebook.run_notebook scheduled__2023-06-29T00:00:00+00:00 [queued]>
[2024-07-18T06:56:06.738+0000] {taskinstance.py:1308} INFO - Starting attempt 1 of 2
[2024-07-18T06:56:06.781+0000] {taskinstance.py:1327} INFO - Executing <Task(PythonOperator): run_notebook> on 2023-06-29 00:00:00+00:00
[2024-07-18T06:56:06.795+0000] {standard_task_runner.py:57} INFO - Started process 9517 to run task
[2024-07-18T06:56:06.826+0000] {standard_task_runner.py:84} INFO - Running: ['***', 'tasks', 'run', 'run_remote_jupyter_notebook', 'run_notebook', 'scheduled__2023-06-29T00:00:00+00:00', '--job-id', '181', '--raw', '--subdir', 'DAGS_FOLDER/run_notebook.py', '--cfg-path', '/tmp/tmp7b95opch']
[2024-07-18T06:56:06.834+0000] {standard_task_runner.py:85} INFO - Job 181: Subtask run_notebook
[2024-07-18T06:56:06.985+0000] {task_command.py:410} INFO - Running <TaskInstance: run_remote_jupyter_notebook.run_notebook scheduled__2023-06-29T00:00:00+00:00 [running]> on host 6c8b3b9a6388
[2024-07-18T06:56:07.187+0000] {taskinstance.py:1547} INFO - Exporting env vars: AIRFLOW_CTX_DAG_OWNER='***' AIRFLOW_CTX_DAG_ID='run_remote_jupyter_notebook' AIRFLOW_CTX_TASK_ID='run_notebook' AIRFLOW_CTX_EXECUTION_DATE='2023-06-29T00:00:00+00:00' AIRFLOW_CTX_TRY_NUMBER='1' AIRFLOW_CTX_DAG_RUN_ID='scheduled__2023-06-29T00:00:00+00:00'
[2024-07-18T06:56:11.049+0000] {logging_mixin.py:149} INFO - Notebook executed and updated successfully on the server.
[2024-07-18T06:56:11.051+0000] {python.py:183} INFO - Done. Returned value was: None
[2024-07-18T06:56:11.066+0000] {taskinstance.py:1350} INFO - Marking task as SUCCESS. dag_id=run_remote_jupyter_notebook, task_id=run_notebook, execution_date=20230629T000000, start_date=20240718T065606, end_date=20240718T065611
[2024-07-18T06:56:11.145+0000] {local_task_job_runner.py:225} INFO - Task exited with return code 0
[2024-07-18T06:56:11.171+0000] {taskinstance.py:2651} INFO - 0 downstream tasks scheduled from follow-on schedule check
