[2024-07-16T07:38:34.499+0000] {taskinstance.py:1103} INFO - Dependencies all met for dep_context=non-requeueable deps ti=<TaskInstance: run_remote_jupyter_notebook.run_notebook scheduled__2024-02-19T00:00:00+00:00 [queued]>
[2024-07-16T07:38:34.506+0000] {taskinstance.py:1103} INFO - Dependencies all met for dep_context=requeueable deps ti=<TaskInstance: run_remote_jupyter_notebook.run_notebook scheduled__2024-02-19T00:00:00+00:00 [queued]>
[2024-07-16T07:38:34.506+0000] {taskinstance.py:1308} INFO - Starting attempt 2 of 2
[2024-07-16T07:38:34.606+0000] {taskinstance.py:1327} INFO - Executing <Task(PythonOperator): run_notebook> on 2024-02-19 00:00:00+00:00
[2024-07-16T07:38:34.611+0000] {standard_task_runner.py:57} INFO - Started process 391 to run task
[2024-07-16T07:38:34.613+0000] {standard_task_runner.py:84} INFO - Running: ['***', 'tasks', 'run', 'run_remote_jupyter_notebook', 'run_notebook', 'scheduled__2024-02-19T00:00:00+00:00', '--job-id', '1298', '--raw', '--subdir', 'DAGS_FOLDER/run_notebook.py', '--cfg-path', '/tmp/tmpje_lo7cf']
[2024-07-16T07:38:34.615+0000] {standard_task_runner.py:85} INFO - Job 1298: Subtask run_notebook
[2024-07-16T07:38:34.654+0000] {task_command.py:410} INFO - Running <TaskInstance: run_remote_jupyter_notebook.run_notebook scheduled__2024-02-19T00:00:00+00:00 [running]> on host edcee86e6774
[2024-07-16T07:38:34.716+0000] {taskinstance.py:1547} INFO - Exporting env vars: AIRFLOW_CTX_DAG_OWNER='***' AIRFLOW_CTX_DAG_ID='run_remote_jupyter_notebook' AIRFLOW_CTX_TASK_ID='run_notebook' AIRFLOW_CTX_EXECUTION_DATE='2024-02-19T00:00:00+00:00' AIRFLOW_CTX_TRY_NUMBER='2' AIRFLOW_CTX_DAG_RUN_ID='scheduled__2024-02-19T00:00:00+00:00'
[2024-07-16T07:38:34.718+0000] {run_notebook.py:14} INFO - Attempting to connect to http://127.0.0.1:8888/tree?token=e8a8150423dfd35bee318800bfcf7c9191ca7485b5cb9fde
[2024-07-16T07:38:34.721+0000] {logging_mixin.py:149} INFO - Error connecting to notebook: HTTPConnectionPool(host='127.0.0.1', port=8888): Max retries exceeded with url: /tree?token=e8a8150423dfd35bee318800bfcf7c9191ca7485b5cb9fde (Caused by NewConnectionError('<urllib3.connection.HTTPConnection object at 0x7f6f50a43cd0>: Failed to establish a new connection: [Errno 111] Connection refused'))
[2024-07-16T07:38:34.722+0000] {taskinstance.py:1824} ERROR - Task failed with exception
Traceback (most recent call last):
  File "/home/airflow/.local/lib/python3.7/site-packages/urllib3/connection.py", line 175, in _new_conn
    (self._dns_host, self.port), self.timeout, **extra_kw
  File "/home/airflow/.local/lib/python3.7/site-packages/urllib3/util/connection.py", line 95, in create_connection
    raise err
  File "/home/airflow/.local/lib/python3.7/site-packages/urllib3/util/connection.py", line 85, in create_connection
    sock.connect(sa)
ConnectionRefusedError: [Errno 111] Connection refused

During handling of the above exception, another exception occurred:

Traceback (most recent call last):
  File "/home/airflow/.local/lib/python3.7/site-packages/urllib3/connectionpool.py", line 710, in urlopen
    chunked=chunked,
  File "/home/airflow/.local/lib/python3.7/site-packages/urllib3/connectionpool.py", line 398, in _make_request
    conn.request(method, url, **httplib_request_kw)
  File "/home/airflow/.local/lib/python3.7/site-packages/urllib3/connection.py", line 244, in request
    super(HTTPConnection, self).request(method, url, body=body, headers=headers)
  File "/usr/local/lib/python3.7/http/client.py", line 1281, in request
    self._send_request(method, url, body, headers, encode_chunked)
  File "/usr/local/lib/python3.7/http/client.py", line 1327, in _send_request
    self.endheaders(body, encode_chunked=encode_chunked)
  File "/usr/local/lib/python3.7/http/client.py", line 1276, in endheaders
    self._send_output(message_body, encode_chunked=encode_chunked)
  File "/usr/local/lib/python3.7/http/client.py", line 1036, in _send_output
    self.send(msg)
  File "/usr/local/lib/python3.7/http/client.py", line 976, in send
    self.connect()
  File "/home/airflow/.local/lib/python3.7/site-packages/urllib3/connection.py", line 205, in connect
    conn = self._new_conn()
  File "/home/airflow/.local/lib/python3.7/site-packages/urllib3/connection.py", line 187, in _new_conn
    self, "Failed to establish a new connection: %s" % e
urllib3.exceptions.NewConnectionError: <urllib3.connection.HTTPConnection object at 0x7f6f50a43cd0>: Failed to establish a new connection: [Errno 111] Connection refused

During handling of the above exception, another exception occurred:

Traceback (most recent call last):
  File "/home/airflow/.local/lib/python3.7/site-packages/requests/adapters.py", line 497, in send
    chunked=chunked,
  File "/home/airflow/.local/lib/python3.7/site-packages/urllib3/connectionpool.py", line 788, in urlopen
    method, url, error=e, _pool=self, _stacktrace=sys.exc_info()[2]
  File "/home/airflow/.local/lib/python3.7/site-packages/urllib3/util/retry.py", line 592, in increment
    raise MaxRetryError(_pool, url, error or ResponseError(cause))
urllib3.exceptions.MaxRetryError: HTTPConnectionPool(host='127.0.0.1', port=8888): Max retries exceeded with url: /tree?token=e8a8150423dfd35bee318800bfcf7c9191ca7485b5cb9fde (Caused by NewConnectionError('<urllib3.connection.HTTPConnection object at 0x7f6f50a43cd0>: Failed to establish a new connection: [Errno 111] Connection refused'))

During handling of the above exception, another exception occurred:

Traceback (most recent call last):
  File "/opt/airflow/dags/run_notebook.py", line 18, in execute_remote_notebook
    response = requests.get(notebook_url, timeout=10)
  File "/home/airflow/.local/lib/python3.7/site-packages/requests/api.py", line 73, in get
    return request("get", url, params=params, **kwargs)
  File "/home/airflow/.local/lib/python3.7/site-packages/requests/api.py", line 59, in request
    return session.request(method=method, url=url, **kwargs)
  File "/home/airflow/.local/lib/python3.7/site-packages/requests/sessions.py", line 587, in request
    resp = self.send(prep, **send_kwargs)
  File "/home/airflow/.local/lib/python3.7/site-packages/requests/sessions.py", line 701, in send
    r = adapter.send(request, **kwargs)
  File "/home/airflow/.local/lib/python3.7/site-packages/requests/adapters.py", line 519, in send
    raise ConnectionError(e, request=request)
requests.exceptions.ConnectionError: HTTPConnectionPool(host='127.0.0.1', port=8888): Max retries exceeded with url: /tree?token=e8a8150423dfd35bee318800bfcf7c9191ca7485b5cb9fde (Caused by NewConnectionError('<urllib3.connection.HTTPConnection object at 0x7f6f50a43cd0>: Failed to establish a new connection: [Errno 111] Connection refused'))

During handling of the above exception, another exception occurred:

Traceback (most recent call last):
  File "/home/airflow/.local/lib/python3.7/site-packages/airflow/operators/python.py", line 181, in execute
    return_value = self.execute_callable()
  File "/home/airflow/.local/lib/python3.7/site-packages/airflow/operators/python.py", line 198, in execute_callable
    return self.python_callable(*self.op_args, **self.op_kwargs)
  File "/opt/airflow/dags/run_notebook.py", line 41, in execute_remote_notebook
    raise AirflowException(f"Failed to connect to Jupyter notebook: {str(e)}")
NameError: name 'AirflowException' is not defined
[2024-07-16T07:38:34.734+0000] {taskinstance.py:1350} INFO - Marking task as FAILED. dag_id=run_remote_jupyter_notebook, task_id=run_notebook, execution_date=20240219T000000, start_date=20240716T073834, end_date=20240716T073834
[2024-07-16T07:38:34.743+0000] {standard_task_runner.py:109} ERROR - Failed to execute job 1298 for task run_notebook (name 'AirflowException' is not defined; 391)
[2024-07-16T07:38:34.787+0000] {local_task_job_runner.py:225} INFO - Task exited with return code 1
[2024-07-16T07:38:34.800+0000] {taskinstance.py:2651} INFO - 0 downstream tasks scheduled from follow-on schedule check
