[2024-07-17T09:50:01.901+0000] {taskinstance.py:1103} INFO - Dependencies all met for dep_context=non-requeueable deps ti=<TaskInstance: run_remote_jupyter_notebook.run_notebook scheduled__2024-07-16T00:00:00+00:00 [queued]>
[2024-07-17T09:50:01.907+0000] {taskinstance.py:1103} INFO - Dependencies all met for dep_context=requeueable deps ti=<TaskInstance: run_remote_jupyter_notebook.run_notebook scheduled__2024-07-16T00:00:00+00:00 [queued]>
[2024-07-17T09:50:01.907+0000] {taskinstance.py:1308} INFO - Starting attempt 1 of 2
[2024-07-17T09:50:01.918+0000] {taskinstance.py:1327} INFO - Executing <Task(PythonOperator): run_notebook> on 2024-07-16 00:00:00+00:00
[2024-07-17T09:50:01.923+0000] {standard_task_runner.py:57} INFO - Started process 217 to run task
[2024-07-17T09:50:01.926+0000] {standard_task_runner.py:84} INFO - Running: ['***', 'tasks', 'run', 'run_remote_jupyter_notebook', 'run_notebook', 'scheduled__2024-07-16T00:00:00+00:00', '--job-id', '1536', '--raw', '--subdir', 'DAGS_FOLDER/run_notebook.py', '--cfg-path', '/tmp/tmpo0qjur7i']
[2024-07-17T09:50:01.928+0000] {standard_task_runner.py:85} INFO - Job 1536: Subtask run_notebook
[2024-07-17T09:50:01.964+0000] {task_command.py:410} INFO - Running <TaskInstance: run_remote_jupyter_notebook.run_notebook scheduled__2024-07-16T00:00:00+00:00 [running]> on host 88b4594b436d
[2024-07-17T09:50:02.043+0000] {taskinstance.py:1547} INFO - Exporting env vars: AIRFLOW_CTX_DAG_OWNER='***' AIRFLOW_CTX_DAG_ID='run_remote_jupyter_notebook' AIRFLOW_CTX_TASK_ID='run_notebook' AIRFLOW_CTX_EXECUTION_DATE='2024-07-16T00:00:00+00:00' AIRFLOW_CTX_TRY_NUMBER='1' AIRFLOW_CTX_DAG_RUN_ID='scheduled__2024-07-16T00:00:00+00:00'
[2024-07-17T09:50:02.078+0000] {logging_mixin.py:149} INFO - Error connecting to notebook: 403 Client Error: Forbidden for url: http://host.docker.internal:8888/api/contents/Notebooks/notebook.ipynb
[2024-07-17T09:50:02.079+0000] {taskinstance.py:1824} ERROR - Task failed with exception
Traceback (most recent call last):
  File "/opt/airflow/dags/run_notebook.py", line 19, in execute_remote_notebook
    response.raise_for_status()
  File "/home/airflow/.local/lib/python3.7/site-packages/requests/models.py", line 1021, in raise_for_status
    raise HTTPError(http_error_msg, response=self)
requests.exceptions.HTTPError: 403 Client Error: Forbidden for url: http://host.docker.internal:8888/api/contents/Notebooks/notebook.ipynb

During handling of the above exception, another exception occurred:

Traceback (most recent call last):
  File "/home/airflow/.local/lib/python3.7/site-packages/airflow/operators/python.py", line 181, in execute
    return_value = self.execute_callable()
  File "/home/airflow/.local/lib/python3.7/site-packages/airflow/operators/python.py", line 198, in execute_callable
    return self.python_callable(*self.op_args, **self.op_kwargs)
  File "/opt/airflow/dags/run_notebook.py", line 48, in execute_remote_notebook
    raise AirflowException(f"Failed to connect to Jupyter notebook: {str(e)}")
NameError: name 'AirflowException' is not defined
[2024-07-17T09:50:02.088+0000] {taskinstance.py:1350} INFO - Marking task as UP_FOR_RETRY. dag_id=run_remote_jupyter_notebook, task_id=run_notebook, execution_date=20240716T000000, start_date=20240717T095001, end_date=20240717T095002
[2024-07-17T09:50:02.101+0000] {standard_task_runner.py:109} ERROR - Failed to execute job 1536 for task run_notebook (name 'AirflowException' is not defined; 217)
[2024-07-17T09:50:02.138+0000] {local_task_job_runner.py:225} INFO - Task exited with return code 1
[2024-07-17T09:50:02.152+0000] {taskinstance.py:2651} INFO - 0 downstream tasks scheduled from follow-on schedule check
[2024-07-18T08:30:37.828+0000] {taskinstance.py:1103} INFO - Dependencies all met for dep_context=non-requeueable deps ti=<TaskInstance: run_remote_jupyter_notebook.run_notebook scheduled__2024-07-16T00:00:00+00:00 [queued]>
[2024-07-18T08:30:37.834+0000] {taskinstance.py:1103} INFO - Dependencies all met for dep_context=requeueable deps ti=<TaskInstance: run_remote_jupyter_notebook.run_notebook scheduled__2024-07-16T00:00:00+00:00 [queued]>
[2024-07-18T08:30:37.835+0000] {taskinstance.py:1308} INFO - Starting attempt 1 of 2
[2024-07-18T08:30:37.845+0000] {taskinstance.py:1327} INFO - Executing <Task(PythonOperator): run_notebook> on 2024-07-16 00:00:00+00:00
[2024-07-18T08:30:37.851+0000] {standard_task_runner.py:57} INFO - Started process 3239 to run task
[2024-07-18T08:30:37.854+0000] {standard_task_runner.py:84} INFO - Running: ['***', 'tasks', 'run', 'run_remote_jupyter_notebook', 'run_notebook', 'scheduled__2024-07-16T00:00:00+00:00', '--job-id', '569', '--raw', '--subdir', 'DAGS_FOLDER/run_notebook.py', '--cfg-path', '/tmp/tmpdg56dewn']
[2024-07-18T08:30:37.855+0000] {standard_task_runner.py:85} INFO - Job 569: Subtask run_notebook
[2024-07-18T08:30:37.890+0000] {task_command.py:410} INFO - Running <TaskInstance: run_remote_jupyter_notebook.run_notebook scheduled__2024-07-16T00:00:00+00:00 [running]> on host e7816f9101dd
[2024-07-18T08:30:37.959+0000] {taskinstance.py:1547} INFO - Exporting env vars: AIRFLOW_CTX_DAG_OWNER='***' AIRFLOW_CTX_DAG_ID='run_remote_jupyter_notebook' AIRFLOW_CTX_TASK_ID='run_notebook' AIRFLOW_CTX_EXECUTION_DATE='2024-07-16T00:00:00+00:00' AIRFLOW_CTX_TRY_NUMBER='1' AIRFLOW_CTX_DAG_RUN_ID='scheduled__2024-07-16T00:00:00+00:00'
[2024-07-18T08:30:39.575+0000] {logging_mixin.py:149} INFO - Notebook executed and updated successfully on the server.
[2024-07-18T08:30:39.575+0000] {python.py:183} INFO - Done. Returned value was: None
[2024-07-18T08:30:39.584+0000] {taskinstance.py:1350} INFO - Marking task as SUCCESS. dag_id=run_remote_jupyter_notebook, task_id=run_notebook, execution_date=20240716T000000, start_date=20240718T083037, end_date=20240718T083039
[2024-07-18T08:30:39.633+0000] {local_task_job_runner.py:225} INFO - Task exited with return code 0
[2024-07-18T08:30:39.648+0000] {taskinstance.py:2651} INFO - 0 downstream tasks scheduled from follow-on schedule check
