[2024-07-15T09:33:24.778+0000] {taskinstance.py:1103} INFO - Dependencies all met for dep_context=non-requeueable deps ti=<TaskInstance: run_jupyter_notebook.run_notebook scheduled__2023-01-24T00:00:00+00:00 [queued]>
[2024-07-15T09:33:24.788+0000] {taskinstance.py:1103} INFO - Dependencies all met for dep_context=requeueable deps ti=<TaskInstance: run_jupyter_notebook.run_notebook scheduled__2023-01-24T00:00:00+00:00 [queued]>
[2024-07-15T09:33:24.789+0000] {taskinstance.py:1308} INFO - Starting attempt 1 of 2
[2024-07-15T09:33:24.890+0000] {taskinstance.py:1327} INFO - Executing <Task(PythonOperator): run_notebook> on 2023-01-24 00:00:00+00:00
[2024-07-15T09:33:24.897+0000] {standard_task_runner.py:57} INFO - Started process 342 to run task
[2024-07-15T09:33:24.901+0000] {standard_task_runner.py:84} INFO - Running: ['***', 'tasks', 'run', 'run_jupyter_notebook', 'run_notebook', 'scheduled__2023-01-24T00:00:00+00:00', '--job-id', '41', '--raw', '--subdir', 'DAGS_FOLDER/run_notebook.py', '--cfg-path', '/tmp/tmp3gg3pi2k']
[2024-07-15T09:33:24.904+0000] {standard_task_runner.py:85} INFO - Job 41: Subtask run_notebook
[2024-07-15T09:33:24.970+0000] {task_command.py:410} INFO - Running <TaskInstance: run_jupyter_notebook.run_notebook scheduled__2023-01-24T00:00:00+00:00 [running]> on host 0aeef3766ac4
[2024-07-15T09:33:25.095+0000] {taskinstance.py:1547} INFO - Exporting env vars: AIRFLOW_CTX_DAG_OWNER='***' AIRFLOW_CTX_DAG_ID='run_jupyter_notebook' AIRFLOW_CTX_TASK_ID='run_notebook' AIRFLOW_CTX_EXECUTION_DATE='2023-01-24T00:00:00+00:00' AIRFLOW_CTX_TRY_NUMBER='1' AIRFLOW_CTX_DAG_RUN_ID='scheduled__2023-01-24T00:00:00+00:00'
[2024-07-15T09:33:25.097+0000] {taskinstance.py:1824} ERROR - Task failed with exception
Traceback (most recent call last):
  File "/home/airflow/.local/lib/python3.7/site-packages/airflow/operators/python.py", line 181, in execute
    return_value = self.execute_callable()
  File "/home/airflow/.local/lib/python3.7/site-packages/airflow/operators/python.py", line 198, in execute_callable
    return self.python_callable(*self.op_args, **self.op_kwargs)
  File "/opt/airflow/dags/run_notebook.py", line 11, in execute_notebook
    with open(notebook_path) as f:
FileNotFoundError: [Errno 2] No such file or directory: './opt/airflow/notebooks/notebook.ipynb'
[2024-07-15T09:33:25.111+0000] {taskinstance.py:1350} INFO - Marking task as UP_FOR_RETRY. dag_id=run_jupyter_notebook, task_id=run_notebook, execution_date=20230124T000000, start_date=20240715T093324, end_date=20240715T093325
[2024-07-15T09:33:25.129+0000] {standard_task_runner.py:109} ERROR - Failed to execute job 41 for task run_notebook ([Errno 2] No such file or directory: './opt/airflow/notebooks/notebook.ipynb'; 342)
[2024-07-15T09:33:25.153+0000] {local_task_job_runner.py:225} INFO - Task exited with return code 1
[2024-07-15T09:33:25.175+0000] {taskinstance.py:2651} INFO - 0 downstream tasks scheduled from follow-on schedule check
