[2024-07-15T09:38:27.436+0000] {taskinstance.py:1103} INFO - Dependencies all met for dep_context=non-requeueable deps ti=<TaskInstance: run_jupyter_notebook.run_notebook scheduled__2023-01-30T00:00:00+00:00 [queued]>
[2024-07-15T09:38:27.450+0000] {taskinstance.py:1103} INFO - Dependencies all met for dep_context=requeueable deps ti=<TaskInstance: run_jupyter_notebook.run_notebook scheduled__2023-01-30T00:00:00+00:00 [queued]>
[2024-07-15T09:38:27.450+0000] {taskinstance.py:1308} INFO - Starting attempt 2 of 2
[2024-07-15T09:38:27.481+0000] {taskinstance.py:1327} INFO - Executing <Task(PythonOperator): run_notebook> on 2023-01-30 00:00:00+00:00
[2024-07-15T09:38:27.489+0000] {standard_task_runner.py:57} INFO - Started process 194 to run task
[2024-07-15T09:38:27.496+0000] {standard_task_runner.py:84} INFO - Running: ['***', 'tasks', 'run', 'run_jupyter_notebook', 'run_notebook', 'scheduled__2023-01-30T00:00:00+00:00', '--job-id', '57', '--raw', '--subdir', 'DAGS_FOLDER/run_notebook.py', '--cfg-path', '/tmp/tmpbz0nsneb']
[2024-07-15T09:38:27.511+0000] {standard_task_runner.py:85} INFO - Job 57: Subtask run_notebook
[2024-07-15T09:38:27.625+0000] {task_command.py:410} INFO - Running <TaskInstance: run_jupyter_notebook.run_notebook scheduled__2023-01-30T00:00:00+00:00 [running]> on host 5239839cd0da
[2024-07-15T09:38:27.789+0000] {taskinstance.py:1547} INFO - Exporting env vars: AIRFLOW_CTX_DAG_OWNER='***' AIRFLOW_CTX_DAG_ID='run_jupyter_notebook' AIRFLOW_CTX_TASK_ID='run_notebook' AIRFLOW_CTX_EXECUTION_DATE='2023-01-30T00:00:00+00:00' AIRFLOW_CTX_TRY_NUMBER='2' AIRFLOW_CTX_DAG_RUN_ID='scheduled__2023-01-30T00:00:00+00:00'
[2024-07-15T09:38:28.530+0000] {launcher.py:166} ERROR - Failed to run command:
['/usr/local/bin/python', '-m', 'ipykernel_launcher', '-f', '/tmp/tmpqpumcm0d.json', '--HistoryManager.hist_file=:memory:']
    PATH='/root/bin:/home/***/.local/bin:/usr/local/bin:/usr/local/sbin:/usr/local/bin:/usr/sbin:/usr/bin:/sbin:/bin'
    with kwargs:
{'stdin': -1, 'stdout': None, 'stderr': None, 'cwd': '/notebooks/', 'start_new_session': True}

[2024-07-15T09:38:28.531+0000] {manager.py:89} ERROR - [Errno 2] No such file or directory: '/notebooks/': '/notebooks/'
Traceback (most recent call last):
  File "/home/airflow/.local/lib/python3.7/site-packages/jupyter_client/manager.py", line 82, in wrapper
    out = await method(self, *args, **kwargs)
  File "/home/airflow/.local/lib/python3.7/site-packages/jupyter_client/manager.py", line 395, in _async_start_kernel
    await ensure_async(self._launch_kernel(kernel_cmd, **kw))
  File "/home/airflow/.local/lib/python3.7/site-packages/jupyter_client/utils.py", line 38, in ensure_async
    return await obj
  File "/home/airflow/.local/lib/python3.7/site-packages/jupyter_client/manager.py", line 311, in _async_launch_kernel
    connection_info = await self.provisioner.launch_kernel(kernel_cmd, **kw)
  File "/home/airflow/.local/lib/python3.7/site-packages/jupyter_client/provisioning/local_provisioner.py", line 204, in launch_kernel
    self.process = launch_kernel(cmd, **scrubbed_kwargs)
  File "/home/airflow/.local/lib/python3.7/site-packages/jupyter_client/launcher.py", line 170, in launch_kernel
    raise ex
  File "/home/airflow/.local/lib/python3.7/site-packages/jupyter_client/launcher.py", line 158, in launch_kernel
    proc = Popen(cmd, **kwargs)
  File "/usr/local/lib/python3.7/subprocess.py", line 800, in __init__
    restore_signals, start_new_session)
  File "/usr/local/lib/python3.7/subprocess.py", line 1551, in _execute_child
    raise child_exception_type(errno_num, err_msg, err_filename)
FileNotFoundError: [Errno 2] No such file or directory: '/notebooks/': '/notebooks/'
[2024-07-15T09:38:28.533+0000] {taskinstance.py:1824} ERROR - Task failed with exception
Traceback (most recent call last):
  File "/home/airflow/.local/lib/python3.7/site-packages/airflow/operators/python.py", line 181, in execute
    return_value = self.execute_callable()
  File "/home/airflow/.local/lib/python3.7/site-packages/airflow/operators/python.py", line 198, in execute_callable
    return self.python_callable(*self.op_args, **self.op_kwargs)
  File "/opt/airflow/dags/run_notebook.py", line 15, in execute_notebook
    ep.preprocess(nb, {'metadata': {'path': '/notebooks/'}})
  File "/home/airflow/.local/lib/python3.7/site-packages/nbconvert/preprocessors/execute.py", line 94, in preprocess
    with self.setup_kernel():
  File "/usr/local/lib/python3.7/contextlib.py", line 112, in __enter__
    return next(self.gen)
  File "/home/airflow/.local/lib/python3.7/site-packages/nbclient/client.py", line 596, in setup_kernel
    self.start_new_kernel(**kwargs)
  File "/home/airflow/.local/lib/python3.7/site-packages/jupyter_core/utils/__init__.py", line 98, in wrapped
    return loop.run_until_complete(inner)
  File "/usr/local/lib/python3.7/asyncio/base_events.py", line 587, in run_until_complete
    return future.result()
  File "/home/airflow/.local/lib/python3.7/site-packages/nbclient/client.py", line 546, in async_start_new_kernel
    await ensure_async(self.km.start_kernel(extra_arguments=self.extra_arguments, **kwargs))
  File "/home/airflow/.local/lib/python3.7/site-packages/jupyter_core/utils/__init__.py", line 110, in ensure_async
    result = await obj
  File "/home/airflow/.local/lib/python3.7/site-packages/jupyter_client/manager.py", line 90, in wrapper
    raise e
  File "/home/airflow/.local/lib/python3.7/site-packages/jupyter_client/manager.py", line 82, in wrapper
    out = await method(self, *args, **kwargs)
  File "/home/airflow/.local/lib/python3.7/site-packages/jupyter_client/manager.py", line 395, in _async_start_kernel
    await ensure_async(self._launch_kernel(kernel_cmd, **kw))
  File "/home/airflow/.local/lib/python3.7/site-packages/jupyter_client/utils.py", line 38, in ensure_async
    return await obj
  File "/home/airflow/.local/lib/python3.7/site-packages/jupyter_client/manager.py", line 311, in _async_launch_kernel
    connection_info = await self.provisioner.launch_kernel(kernel_cmd, **kw)
  File "/home/airflow/.local/lib/python3.7/site-packages/jupyter_client/provisioning/local_provisioner.py", line 204, in launch_kernel
    self.process = launch_kernel(cmd, **scrubbed_kwargs)
  File "/home/airflow/.local/lib/python3.7/site-packages/jupyter_client/launcher.py", line 170, in launch_kernel
    raise ex
  File "/home/airflow/.local/lib/python3.7/site-packages/jupyter_client/launcher.py", line 158, in launch_kernel
    proc = Popen(cmd, **kwargs)
  File "/usr/local/lib/python3.7/subprocess.py", line 800, in __init__
    restore_signals, start_new_session)
  File "/usr/local/lib/python3.7/subprocess.py", line 1551, in _execute_child
    raise child_exception_type(errno_num, err_msg, err_filename)
FileNotFoundError: [Errno 2] No such file or directory: '/notebooks/': '/notebooks/'
[2024-07-15T09:38:28.545+0000] {taskinstance.py:1350} INFO - Marking task as FAILED. dag_id=run_jupyter_notebook, task_id=run_notebook, execution_date=20230130T000000, start_date=20240715T093827, end_date=20240715T093828
[2024-07-15T09:38:28.565+0000] {standard_task_runner.py:109} ERROR - Failed to execute job 57 for task run_notebook ([Errno 2] No such file or directory: '/notebooks/': '/notebooks/'; 194)
[2024-07-15T09:38:28.603+0000] {local_task_job_runner.py:225} INFO - Task exited with return code 1
[2024-07-15T09:38:28.619+0000] {taskinstance.py:2651} INFO - 0 downstream tasks scheduled from follow-on schedule check
